Workbook
Name Slicer_Sector: #N/A

Sheet CPI Dashboard

Sheet Objective 
B2: Objective
B3: The objective of this case study is to analyze India’s inflation patterns using Consumer Price Index (CPI) data. The CPI tracks changes in the price of a fixed basket of goods and services over time and reflects
B4: inflation trends faced by Indian consumers.
B5: This project aims to:
B6: 1. Identify the contribution of major CPI categories toward overall inflation,
B7: 2. Examine year-over-year inflation trends,
B8: 3. Evaluate food price inflation,
B9: 4. Assess the impact of COVID-19, and
B10: 5. Analyze how global crude oil fluctuations influence India’s inflation.

Sheet All_India_Index_Upto_April23
A1: Sector | B1: Year | C1: Month | D1: Cereals and products | E1: Meat and fish | F1: Egg | G1: Milk and products | H1: Oils and fats | I1: Fruits | J1: Vegetables | K1: Pulses and products | L1: Sugar and Confectionery | M1: Spices | N1: Non-alcoholic beverages | O1: Prepared meals, snacks, sweets etc. | P1: Food and beverages | Q1: Pan, tobacco and intoxicants | R1: Clothing | S1: Footwear | T1: Clothing and footwear | U1: Housing | V1: Fuel and light | W1: Household goods and services | X1: Health | Y1: Transport and communication | Z1: Recreation and amusement | AA1: Education | AB1: Personal care and effects | AC1: Miscellaneous | AD1: General index
A2: Rural | B2: 2013 | C2: January | D2: 107.5 | E2: 106.3 | F2: 108.1 | G2: 104.9 | H2: 106.1 | I2: 103.9 | J2: 101.9 | K2: 106.1 | L2: 106.8 | M2: 103.1 | N2: 104.8 | O2: 106.7 | P2: 105.5 | Q2: 105.1 | R2: 106.5 | S2: 105.8 | T2: 106.4 | U2: NA | V2: 105.5 | W2: 104.8 | X2: 104 | Y2: 103.3 | Z2: 103.4 | AA2: 103.8 | AB2: 104.7 | AC2: 104 | AD2: 105.1
A3: Urban | B3: 2013 | C3: January | D3: 110.5 | E3: 109.1 | F3: 113 | G3: 103.6 | H3: 103.4 | I3: 102.3 | J3: 102.9 | K3: 105.8 | L3: 105.1 | M3: 101.8 | N3: 105.1 | O3: 107.9 | P3: 105.9 | Q3: 105.2 | R3: 105.9 | S3: 105 | T3: 105.8 | U3: 100.3 | V3: 105.4 | W3: 104.8 | X3: 104.1 | Y3: 103.2 | Z3: 102.9 | AA3: 103.5 | AB3: 104.3 | AC3: 103.7 | AD3: 104
A4: Rural+Urban | B4: 2013 | C4: January | D4: 108.4 | E4: 107.3 | F4: 110 | G4: 104.4 | H4: 105.1 | I4: 103.2 | J4: 102.2 | K4: 106 | L4: 106.2 | M4: 102.7 | N4: 104.9 | O4: 107.3 | P4: 105.6 | Q4: 105.1 | R4: 106.3 | S4: 105.5 | T4: 106.2 | U4: 100.3 | V4: 105.5 | W4: 104.8 | X4: 104 | Y4: 103.2 | Z4: 103.1 | AA4: 103.6 | AB4: 104.5 | AC4: 103.9 | AD4: 104.6
A5: Rural | B5: 2013 | C5: February | D5: 109.2 | E5: 108.7 | F5: 110.2 | G5: 105.4 | H5: 106.7 | I5: 104 | J5: 102.4 | K5: 105.9 | L5: 105.7 | M5: 103.1 | N5: 105.1 | O5: 107.7 | P5: 106.3 | Q5: 105.6 | R5: 107.1 | S5: 106.3 | T5: 107 | U5: NA | V5: 106.2 | W5: 105.2 | X5: 104.4 | Y5: 103.9 | Z5: 104 | AA5: 104.1 | AB5: 104.6 | AC5: 104.4 | AD5: 105.8
A6: Urban | B6: 2013 | C6: February | D6: 112.9 | E6: 112.9 | F6: 116.9 | G6: 104 | H6: 103.5 | I6: 103.1 | J6: 104.9 | K6: 104.1 | L6: 103.8 | M6: 102.3 | N6: 106 | O6: 109 | P6: 107.2 | Q6: 106 | R6: 106.6 | S6: 105.5 | T6: 106.4 | U6: 100.4 | V6: 105.7 | W6: 105.2 | X6: 104.7 | Y6: 104.4 | Z6: 103.3 | AA6: 103.7 | AB6: 104.3 | AC6: 104.3 | AD6: 104.7
A7: Rural+Urban | B7: 2013 | C7: February | D7: 110.4 | E7: 110.2 | F7: 112.8 | G7: 104.9 | H7: 105.5 | I7: 103.6 | J7: 103.2 | K7: 105.3 | L7: 105.1 | M7: 102.8 | N7: 105.5 | O7: 108.3 | P7: 106.6 | Q7: 105.7 | R7: 106.9 | S7: 106 | T7: 106.8 | U7: 100.4 | V7: 106 | W7: 105.2 | X7: 104.5 | Y7: 104.2 | Z7: 103.6 | AA7: 103.9 | AB7: 104.5 | AC7: 104.4 | AD7: 105.3
A8: Rural | B8: 2013 | C8: March | D8: 110.2 | E8: 108.8 | F8: 109.9 | G8: 105.6 | H8: 106.2 | I8: 105.7 | J8: 101.4 | K8: 105.7 | L8: 105 | M8: 103.3 | N8: 105.6 | O8: 108.2 | P8: 106.6 | Q8: 106.5 | R8: 107.6 | S8: 106.8 | T8: 107.5 | U8: NA | V8: 106.1 | W8: 105.6 | X8: 104.7 | Y8: 104.6 | Z8: 104 | AA8: 104.3 | AB8: 104.3 | AC8: 104.6 | AD8: 106
A9: Urban | B9: 2013 | C9: March | D9: 113.9 | E9: 111.4 | F9: 113.2 | G9: 104.3 | H9: 102.7 | I9: 104.9 | J9: 103.8 | K9: 103.5 | L9: 102.6 | M9: 102.4 | N9: 107 | O9: 109.8 | P9: 107.3 | Q9: 106.8 | R9: 107.2 | S9: 106 | T9: 107 | U9: 100.4 | V9: 106 | W9: 105.7 | X9: 105.2 | Y9: 105.5 | Z9: 103.5 | AA9: 103.8 | AB9: 104.2 | AC9: 104.9 | AD9: 105
A10: Rural+Urban | B10: 2013 | C10: March | D10: 111.4 | E10: 109.7 | F10: 111.2 | G10: 105.1 | H10: 104.9 | I10: 105.3 | J10: 102.2 | K10: 105 | L10: 104.2 | M10: 103 | N10: 106.2 | O10: 108.9 | P10: 106.9 | Q10: 106.6 | R10: 107.4 | S10: 106.5 | T10: 107.3 | U10: 100.4 | V10: 106.1 | W10: 105.6 | X10: 104.9 | Y10: 105.1 | Z10: 103.7 | AA10: 104 | AB10: 104.3 | AC10: 104.7 | AD10: 105.5
A11: Rural | B11: 2013 | C11: April | D11: 110.2 | E11: 109.5 | F11: 106.9 | G11: 106.3 | H11: 105.7 | I11: 108.3 | J11: 103.4 | K11: 105.7 | L11: 104.2 | M11: 103.2 | N11: 106.5 | O11: 108.8 | P11: 107.1 | Q11: 107.1 | R11: 108.1 | S11: 107.4 | T11: 108 | U11: NA | V11: 106.5 | W11: 106.1 | X11: 105.1 | Y11: 104.4 | Z11: 104.5 | AA11: 104.8 | AB11: 102.7 | AC11: 104.6 | AD11: 106.4
A12: Urban | B12: 2013 | C12: April | D12: 114.6 | E12: 113.4 | F12: 106 | G12: 104.7 | H12: 102.1 | I12: 109.5 | J12: 109.7 | K12: 104.6 | L12: 102 | M12: 103.5 | N12: 108.2 | O12: 110.6 | P12: 108.8 | Q12: 108.5 | R12: 107.9 | S12: 106.4 | T12: 107.7 | U12: 100.5 | V12: 106.4 | W12: 106.5 | X12: 105.7 | Y12: 105 | Z12: 104 | AA12: 105.2 | AB12: 103.2 | AC12: 105.1 | AD12: 105.7
A13: Rural+Urban | B13: 2013 | C13: April | D13: 111.6 | E13: 110.9 | F13: 106.6 | G13: 105.7 | H13: 104.4 | I13: 108.9 | J13: 105.5 | K13: 105.3 | L13: 103.5 | M13: 103.3 | N13: 107.2 | O13: 109.6 | P13: 107.7 | Q13: 107.5 | R13: 108 | S13: 107 | T13: 107.9 | U13: 100.5 | V13: 106.5 | W13: 106.3 | X13: 105.3 | Y13: 104.7 | Z13: 104.2 | AA13: 105 | AB13: 102.9 | AC13: 104.8 | AD13: 106.1
A14: Rural | B14: 2013 | C14: May | D14: 110.9 | E14: 109.8 | F14: 105.9 | G14: 107.5 | H14: 105.3 | I14: 108.1 | J14: 107.3 | K14: 106.1 | L14: 103.7 | M14: 104 | N14: 107.4 | O14: 109.9 | P14: 108.1 | Q14: 108.1 | R14: 108.8 | S14: 107.9 | T14: 108.6 | U14: NA | V14: 107.5 | W14: 106.8 | X14: 105.7 | Y14: 104.1 | Z14: 105 | AA14: 105.5 | AB14: 102.1 | AC14: 104.8 | AD14: 107.2
A15: Urban | B15: 2013 | C15: May | D15: 115.4 | E15: 114.2 | F15: 102.7 | G15: 105.5 | H15: 101.5 | I15: 110.6 | J15: 123.7 | K15: 105.2 | L15: 101.9 | M15: 105 | N15: 109.1 | O15: 111.3 | P15: 111.1 | Q15: 109.8 | R15: 108.5 | S15: 106.7 | T15: 108.3 | U15: 100.5 | V15: 107.2 | W15: 107.1 | X15: 106.2 | Y15: 103.9 | Z15: 104.6 | AA15: 105.7 | AB15: 102.6 | AC15: 104.9 | AD15: 106.6
A16: Rural+Urban | B16: 2013 | C16: May | D16: 112.3 | E16: 111.3 | F16: 104.7 | G16: 106.8 | H16: 103.9 | I16: 109.3 | J16: 112.9 | K16: 105.8 | L16: 103.1 | M16: 104.3 | N16: 108.1 | O16: 110.5 | P16: 109.2 | Q16: 108.6 | R16: 108.7 | S16: 107.4 | T16: 108.5 | U16: 100.5 | V16: 107.4 | W16: 106.9 | X16: 105.9 | Y16: 104 | Z16: 104.8 | AA16: 105.6 | AB16: 102.3 | AC16: 104.8 | AD16: 106.9
A17: Rural | B17: 2013 | C17: June | D17: 112.3 | E17: 112.1 | F17: 108.1 | G17: 108.3 | H17: 105.9 | I17: 109.2 | J17: 118 | K17: 106.8 | L17: 104.1 | M17: 105.4 | N17: 108.2 | O17: 111 | P17: 110.6 | Q17: 109 | R17: 109.7 | S17: 108.8 | T17: 109.5 | U17: NA | V17: 108.5 | W17: 107.5 | X17: 106.3 | Y17: 105 | Z17: 105.6 | AA17: 106.5 | AB17: 102.5 | AC17: 105.5 | AD17: 108.9
A18: Urban | B18: 2013 | C18: June | D18: 117 | E18: 120.1 | F18: 112.5 | G18: 107.3 | H18: 101.3 | I18: 112.4 | J18: 143.6 | K18: 105.4 | L18: 101.4 | M18: 106.4 | N18: 110 | O18: 112.2 | P18: 115 | Q18: 110.9 | R18: 109.2 | S18: 107.2 | T18: 108.9 | U18: 106.6 | V18: 108 | W18: 107.7 | X18: 106.5 | Y18: 105.2 | Z18: 105.2 | AA18: 108.1 | AB18: 103.3 | AC18: 106.1 | AD18: 109.7
A19: Rural+Urban | B19: 2013 | C19: June | D19: 113.8 | E19: 114.9 | F19: 109.8 | G19: 107.9 | H19: 104.2 | I19: 110.7 | J19: 126.7 | K19: 106.3 | L19: 103.2 | M19: 105.7 | N19: 109 | O19: 111.6 | P19: 112.2 | Q19: 109.5 | R19: 109.5 | S19: 108.1 | T19: 109.3 | U19: 106.6 | V19: 108.3 | W19: 107.6 | X19: 106.4 | Y19: 105.1 | Z19: 105.4 | AA19: 107.4 | AB19: 102.8 | AC19: 105.8 | AD19: 109.3
A20: Rural | B20: 2013 | C20: July | D20: 113.4 | E20: 114.9 | F20: 110.5 | G20: 109.3 | H20: 106.2 | I20: 110.3 | J20: 129.2 | K20: 107.1 | L20: 104.3 | M20: 106.4 | N20: 109.1 | O20: 112.1 | P20: 113.1 | Q20: 109.8 | R20: 110.5 | S20: 109.5 | T20: 110.3 | U20: NA | V20: 109.5 | W20: 108.3 | X20: 106.9 | Y20: 106.8 | Z20: 106.4 | AA20: 107.8 | AB20: 102.5 | AC20: 106.5 | AD20: 110.7
A21: Urban | B21: 2013 | C21: July | D21: 117.8 | E21: 119.2 | F21: 114 | G21: 108.3 | H21: 101.1 | I21: 113.2 | J21: 160.9 | K21: 105.1 | L21: 101.3 | M21: 107.5 | N21: 110.4 | O21: 113.1 | P21: 117.5 | Q21: 111.7 | R21: 109.8 | S21: 107.8 | T21: 109.5 | U21: 107.7 | V21: 108.6 | W21: 108.1 | X21: 107.1 | Y21: 107.3 | Z21: 105.9 | AA21: 110.1 | AB21: 103.2 | AC21: 107.3 | AD21: 111.4
A22: Rural+Urban | B22: 2013 | C22: July | D22: 114.8 | E22: 116.4 | F22: 111.9 | G22: 108.9 | H22: 104.3 | I22: 111.7 | J22: 140 | K22: 106.4 | L22: 103.3 | M22: 106.8 | N22: 109.6 | O22: 112.6 | P22: 114.7 | Q22: 110.3 | R22: 110.2 | S22: 108.8 | T22: 110 | U22: 107.7 | V22: 109.2 | W22: 108.2 | X22: 107 | Y22: 107.1 | Z22: 106.1 | AA22: 109.1 | AB22: 102.8 | AC22: 106.9 | AD22: 111
A23: Rural | B23: 2013 | C23: August | D23: 114.3 | E23: 115.4 | F23: 111.1 | G23: 110 | H23: 106.4 | I23: 110.8 | J23: 138.9 | K23: 107.4 | L23: 104.1 | M23: 106.9 | N23: 109.7 | O23: 112.6 | P23: 114.9 | Q23: 110.7 | R23: 111.3 | S23: 110.2 | T23: 111.1 | U23: NA | V23: 109.9 | W23: 108.7 | X23: 107.5 | Y23: 107.8 | Z23: 106.8 | AA23: 108.7 | AB23: 105 | AC23: 107.5 | AD23: 112.1
A24: Urban | B24: 2013 | C24: August | D24: 118.3 | E24: 120.4 | F24: 112.7 | G24: 108.9 | H24: 101.1 | I24: 108.7 | J24: 177 | K24: 104.7 | L24: 101 | M24: 108.5 | N24: 110.9 | O24: 114.3 | P24: 119.6 | Q24: 112.4 | R24: 110.6 | S24: 108.3 | T24: 110.2 | U24: 108.9 | V24: 109.3 | W24: 108.7 | X24: 107.6 | Y24: 108.1 | Z24: 106.5 | AA24: 110.8 | AB24: 106 | AC24: 108.3 | AD24: 112.7
A25: Rural+Urban | B25: 2013 | C25: August | D25: 115.6 | E25: 117.2 | F25: 111.7 | G25: 109.6 | H25: 104.5 | I25: 109.8 | J25: 151.8 | K25: 106.5 | L25: 103.1 | M25: 107.4 | N25: 110.2 | O25: 113.4 | P25: 116.6 | Q25: 111.2 | R25: 111 | S25: 109.4 | T25: 110.7 | U25: 108.9 | V25: 109.7 | W25: 108.7 | X25: 107.5 | Y25: 108 | Z25: 106.6 | AA25: 109.9 | AB25: 105.4 | AC25: 107.9 | AD25: 112.4
A26: Rural | B26: 2013 | C26: September | D26: 115.4 | E26: 115.7 | F26: 111.7 | G26: 111 | H26: 107.4 | I26: 110.9 | J26: 154 | K26: 108.1 | L26: 104.2 | M26: 107.9 | N26: 110.4 | O26: 114 | P26: 117.8 | Q26: 111.7 | R26: 112.7 | S26: 111.4 | T26: 112.5 | U26: NA | V26: 111.1 | W26: 109.6 | X26: 108.3 | Y26: 109.3 | Z26: 107.7 | AA26: 109.8 | AB26: 106.7 | AC26: 108.7 | AD26: 114.2
A27: Urban | B27: 2013 | C27: September | D27: 118.6 | E27: 119.1 | F27: 113.2 | G27: 109.6 | H27: 101.7 | I27: 103.2 | J27: 174.3 | K27: 105.1 | L27: 100.8 | M27: 109.1 | N27: 111.1 | O27: 115.4 | P27: 119.2 | Q27: 112.9 | R27: 111.4 | S27: 109 | T27: 111.1 | U27: 109.7 | V27: 109.5 | W27: 109.6 | X27: 107.9 | Y27: 110.4 | Z27: 107.4 | AA27: 111.2 | AB27: 106.9 | AC27: 109.4 | AD27: 113.2
A28: Rural+Urban | B28: 2013 | C28: September | D28: 116.4 | E28: 116.9 | F28: 112.3 | G28: 110.5 | H28: 105.3 | I28: 107.3 | J28: 160.9 | K28: 107.1 | L28: 103.1 | M28: 108.3 | N28: 110.7 | O28: 114.6 | P28: 118.3 | Q28: 112 | R28: 112.2 | S28: 110.4 | T28: 111.9 | U28: 109.7 | V28: 110.5 | W28: 109.6 | X28: 108.1 | Y28: 109.9 | Z28: 107.5 | AA28: 110.6 | AB28: 106.8 | AC28: 109 | AD28: 113.7
A29: Rural | B29: 2013 | C29: October | D29: 116.3 | E29: 115.4 | F29: 112.6 | G29: 111.7 | H29: 107.7 | I29: 113.2 | J29: 164.9 | K29: 108.3 | L29: 103.9 | M29: 108.2 | N29: 111.1 | O29: 114.9 | P29: 119.8 | Q29: 112.2 | R29: 113.6 | S29: 112.3 | T29: 113.4 | U29: NA | V29: 111.6 | W29: 110.4 | X29: 108.9 | Y29: 109.3 | Z29: 108.3 | AA29: 110.2 | AB29: 107.5 | AC29: 109.1 | AD29: 115.5
A30: Urban | B30: 2013 | C30: October | D30: 118.9 | E30: 118.1 | F30: 114.5 | G30: 110.4 | H30: 102.3 | I30: 106.2 | J30: 183.5 | K30: 105.3 | L30: 100.2 | M30: 109.6 | N30: 111.4 | O30: 116 | P30: 120.8 | Q30: 113.5 | R30: 112.5 | S30: 109.7 | T30: 112 | U30: 110.5 | V30: 109.7 | W30: 110.2 | X30: 108.2 | Y30: 109.7 | Z30: 108 | AA30: 111.3 | AB30: 107.3 | AC30: 109.4 | AD30: 114
A31: Rural+Urban | B31: 2013 | C31: October | D31: 117.1 | E31: 116.3 | F31: 113.3 | G31: 111.2 | H31: 105.7 | I31: 109.9 | J31: 171.2 | K31: 107.3 | L31: 102.7 | M31: 108.7 | N31: 111.2 | O31: 115.4 | P31: 120.2 | Q31: 112.5 | R31: 113.2 | S31: 111.2 | T31: 112.8 | U31: 110.5 | V31: 110.9 | W31: 110.3 | X31: 108.6 | Y31: 109.5 | Z31: 108.1 | AA31: 110.8 | AB31: 107.4 | AC31: 109.2 | AD31: 114.8
A32: Rural | B32: 2013 | C32: November | D32: 117.3 | E32: 114.9 | F32: 116.2 | G32: 112.8 | H32: 108.9 | I32: 116.6 | J32: 178.1 | K32: 109.1 | L32: 103.6 | M32: 109 | N32: 111.8 | O32: 116 | P32: 122.5 | Q32: 112.8 | R32: 114.6 | S32: 113.1 | T32: 114.4 | U32: NA | V32: 112.6 | W32: 111.3 | X32: 109.7 | Y32: 109.6 | Z32: 108.7 | AA32: 111 | AB32: 108.2 | AC32: 109.8 | AD32: 117.4
A33: Urban | B33: 2013 | C33: November | D33: 119.8 | E33: 116.3 | F33: 122.6 | G33: 112 | H33: 103.2 | I33: 110 | J33: 192.8 | K33: 106.3 | L33: 99.5 | M33: 110.3 | N33: 111.8 | O33: 117.1 | P33: 122.9 | Q33: 114.1 | R33: 113.5 | S33: 110.3 | T33: 113 | U33: 111.1 | V33: 110 | W33: 110.9 | X33: 108.6 | Y33: 109.5 | Z33: 108.5 | AA33: 111.3 | AB33: 107.9 | AC33: 109.6 | AD33: 115
A34: Rural+Urban | B34: 2013 | C34: November | D34: 118.1 | E34: 115.4 | F34: 118.7 | G34: 112.5 | H34: 106.8 | I34: 113.5 | J34: 183.1 | K34: 108.2 | L34: 102.2 | M34: 109.4 | N34: 111.8 | O34: 116.5 | P34: 122.6 | Q34: 113.1 | R34: 114.2 | S34: 111.9 | T34: 113.8 | U34: 111.1 | V34: 111.6 | W34: 111.1 | X34: 109.3 | Y34: 109.5 | Z34: 108.6 | AA34: 111.2 | AB34: 108.1 | AC34: 109.7 | AD34: 116.3
A35: Rural | B35: 2013 | C35: December | D35: 118.4 | E35: 115.9 | F35: 120.4 | G35: 113.8 | H35: 109.5 | I35: 115.5 | J35: 145.7 | K35: 109.5 | L35: 102.9 | M35: 109.8 | N35: 112.1 | O35: 116.8 | P35: 118.7 | Q35: 113.6 | R35: 115.8 | S35: 114 | T35: 115.5 | U35: NA | V35: 112.8 | W35: 112.1 | X35: 110.1 | Y35: 109.9 | Z35: 109.2 | AA35: 111.6 | AB35: 108.1 | AC35: 110.1 | AD35: 115.5
A36: Urban | B36: 2013 | C36: December | D36: 120.5 | E36: 118.1 | F36: 128.5 | G36: 112.8 | H36: 103.4 | I36: 110.7 | J36: 144.8 | K36: 107.1 | L36: 98.6 | M36: 111.9 | N36: 112.1 | O36: 118.1 | P36: 117.8 | Q36: 115 | R36: 114.2 | S36: 110.9 | T36: 113.7 | U36: 110.7 | V36: 110.4 | W36: 111.3 | X36: 109 | Y36: 109.7 | Z36: 108.9 | AA36: 111.4 | AB36: 107.7 | AC36: 109.8 | AD36: 113.3
A37: Rural+Urban | B37: 2013 | C37: December | D37: 119.1 | E37: 116.7 | F37: 123.5 | G37: 113.4 | H37: 107.3 | I37: 113.3 | J37: 145.4 | K37: 108.7 | L37: 101.5 | M37: 110.5 | N37: 112.1 | O37: 117.4 | P37: 118.4 | Q37: 114 | R37: 115.2 | S37: 112.7 | T37: 114.8 | U37: 110.7 | V37: 111.9 | W37: 111.7 | X37: 109.7 | Y37: 109.8 | Z37: 109 | AA37: 111.5 | AB37: 107.9 | AC37: 110 | AD37: 114.5
A38: Rural | B38: 2014 | C38: January | D38: 118.9 | E38: 117.1 | F38: 120.5 | G38: 114.4 | H38: 109 | I38: 115.5 | J38: 123.9 | K38: 109.6 | L38: 101.8 | M38: 110.2 | N38: 112.4 | O38: 117.3 | P38: 116 | Q38: 114 | R38: 116.5 | S38: 114.5 | T38: 116.2 | U38: NA | V38: 113 | W38: 112.6 | X38: 110.6 | Y38: 110.5 | Z38: 109.6 | AA38: 111.8 | AB38: 108.3 | AC38: 110.6 | AD38: 114.2
A39: Urban | B39: 2014 | C39: January | D39: 121.2 | E39: 122 | F39: 129.9 | G39: 113.6 | H39: 102.9 | I39: 112.1 | J39: 118.9 | K39: 107.5 | L39: 96.9 | M39: 112.7 | N39: 112.1 | O39: 119 | P39: 115.5 | Q39: 115.7 | R39: 114.8 | S39: 111.3 | T39: 114.3 | U39: 111.6 | V39: 111 | W39: 111.9 | X39: 109.7 | Y39: 110.8 | Z39: 109.8 | AA39: 111.5 | AB39: 108 | AC39: 110.5 | AD39: 112.9
A40: Rural+Urban | B40: 2014 | C40: January | D40: 119.6 | E40: 118.8 | F40: 124.1 | G40: 114.1 | H40: 106.8 | I40: 113.9 | J40: 122.2 | K40: 108.9 | L40: 100.2 | M40: 111 | N40: 112.3 | O40: 118.1 | P40: 115.8 | Q40: 114.5 | R40: 115.8 | S40: 113.2 | T40: 115.4 | U40: 111.6 | V40: 112.2 | W40: 112.3 | X40: 110.3 | Y40: 110.7 | Z40: 109.7 | AA40: 111.6 | AB40: 108.2 | AC40: 110.6 | AD40: 113.6
...

Sheet CPI Data
A1: Sector | B1: Year | C1: Month | D1: Time Period | E1: Cereals and products | F1: Meat and fish | G1: Egg | H1: Milk and products | I1: Oils and fats | J1: Fruits | K1: Vegetables | L1: Pulses and products | M1: Sugar and Confectionery | N1: Spices | O1: Non-alcoholic beverages | P1: Prepared meals, snacks, sweets etc. | Q1: Food and beverages | R1: Pan, tobacco and intoxicants | S1: Clothing | T1: Footwear | U1: Clothing and footwear | V1: Housing | W1: Fuel and light | X1: Household goods and services | Y1: Health | Z1: Transport and communication | AA1: Recreation and amusement | AB1: Education | AC1: Personal care and effects | AD1: Miscellaneous | AE1: General index | AF1: FOOD | AG1: CLOTHING | AH1: ESSENTIAL | AI1: HEALTH | AJ1: ENERGY | AK1: LUXURY
A2: Rural | B2: 2013 | C2: January | D2: =B2&" "&C2 -> 2013 January | E2: 107.5 | F2: 106.3 | G2: 108.1 | H2: 104.9 | I2: 106.1 | J2: 103.9 | K2: 101.9 | L2: 106.1 | M2: 106.8 | N2: 103.1 | O2: 104.8 | P2: 106.7 | Q2: 105.5 | R2: 105.1 | S2: 106.5 | T2: 105.8 | U2: 106.4 | V2: 100.3 | W2: 105.5 | X2: 104.8 | Y2: 104 | Z2: 103.3 | AA2: 103.4 | AB2: 103.8 | AC2: 104.7 | AD2: 104 | AE2: 105.1 | AF2: =SUM($E2:$Q2) -> 1371.7 | AG2: =SUM($S2:$U2) -> 318.7 | AH2: =SUM(V2,X2,AB2) -> 308.9 | AI2: =SUM(Y2,AC2) -> 208.7 | AJ2: =SUM(W2,Z2) -> 208.8 | AK2: =SUM(R2,AA2,AD2) -> 312.5
A3: Urban | B3: 2013 | C3: January | D3: =B3&" "&C3 -> 2013 January | E3: 110.5 | F3: 109.1 | G3: 113 | H3: 103.6 | I3: 103.4 | J3: 102.3 | K3: 102.9 | L3: 105.8 | M3: 105.1 | N3: 101.8 | O3: 105.1 | P3: 107.9 | Q3: 105.9 | R3: 105.2 | S3: 105.9 | T3: 105 | U3: 105.8 | V3: 100.3 | W3: 105.4 | X3: 104.8 | Y3: 104.1 | Z3: 103.2 | AA3: 102.9 | AB3: 103.5 | AC3: 104.3 | AD3: 103.7 | AE3: 104 | AF3: =SUM($E3:$Q3) -> 1376.4 | AG3: =SUM($S3:$U3) -> 316.7 | AH3: =SUM(V3,X3,AB3) -> 308.6 | AI3: =SUM(Y3,AC3) -> 208.4 | AJ3: =SUM(W3,Z3) -> 208.6 | AK3: =SUM(R3,AA3,AD3) -> 311.8
A4: Rural+Urban | B4: 2013 | C4: January | D4: =B4&" "&C4 -> 2013 January | E4: 108.4 | F4: 107.3 | G4: 110 | H4: 104.4 | I4: 105.1 | J4: 103.2 | K4: 102.2 | L4: 106 | M4: 106.2 | N4: 102.7 | O4: 104.9 | P4: 107.3 | Q4: 105.6 | R4: 105.1 | S4: 106.3 | T4: 105.5 | U4: 106.2 | V4: 100.3 | W4: 105.5 | X4: 104.8 | Y4: 104 | Z4: 103.2 | AA4: 103.1 | AB4: 103.6 | AC4: 104.5 | AD4: 103.9 | AE4: 104.6 | AF4: =SUM($E4:$Q4) -> 1373.3 | AG4: =SUM($S4:$U4) -> 318 | AH4: =SUM(V4,X4,AB4) -> 308.7 | AI4: =SUM(Y4,AC4) -> 208.5 | AJ4: =SUM(W4,Z4) -> 208.7 | AK4: =SUM(R4,AA4,AD4) -> 312.1
A5: Rural | B5: 2013 | C5: February | D5: =B5&" "&C5 -> 2013 February | E5: 109.2 | F5: 108.7 | G5: 110.2 | H5: 105.4 | I5: 106.7 | J5: 104 | K5: 102.4 | L5: 105.9 | M5: 105.7 | N5: 103.1 | O5: 105.1 | P5: 107.7 | Q5: 106.3 | R5: 105.6 | S5: 107.1 | T5: 106.3 | U5: 107 | V5: 100.4 | W5: 106.2 | X5: 105.2 | Y5: 104.4 | Z5: 103.9 | AA5: 104 | AB5: 104.1 | AC5: 104.6 | AD5: 104.4 | AE5: 105.8 | AF5: =SUM($E5:$Q5) -> 1380.4 | AG5: =SUM($S5:$U5) -> 320.4 | AH5: =SUM(V5,X5,AB5) -> 309.7 | AI5: =SUM(Y5,AC5) -> 209 | AJ5: =SUM(W5,Z5) -> 210.1 | AK5: =SUM(R5,AA5,AD5) -> 314
A6: Urban | B6: 2013 | C6: February | D6: =B6&" "&C6 -> 2013 February | E6: 112.9 | F6: 112.9 | G6: 116.9 | H6: 104 | I6: 103.5 | J6: 103.1 | K6: 104.9 | L6: 104.1 | M6: 103.8 | N6: 102.3 | O6: 106 | P6: 109 | Q6: 107.2 | R6: 106 | S6: 106.6 | T6: 105.5 | U6: 106.4 | V6: 100.4 | W6: 105.7 | X6: 105.2 | Y6: 104.7 | Z6: 104.4 | AA6: 103.3 | AB6: 103.7 | AC6: 104.3 | AD6: 104.3 | AE6: 104.7 | AF6: =SUM($E6:$Q6) -> 1390.6 | AG6: =SUM($S6:$U6) -> 318.5 | AH6: =SUM(V6,X6,AB6) -> 309.3 | AI6: =SUM(Y6,AC6) -> 209 | AJ6: =SUM(W6,Z6) -> 210.1 | AK6: =SUM(R6,AA6,AD6) -> 313.6
A7: Rural+Urban | B7: 2013 | C7: February | D7: =B7&" "&C7 -> 2013 February | E7: 110.4 | F7: 110.2 | G7: 112.8 | H7: 104.9 | I7: 105.5 | J7: 103.6 | K7: 103.2 | L7: 105.3 | M7: 105.1 | N7: 102.8 | O7: 105.5 | P7: 108.3 | Q7: 106.6 | R7: 105.7 | S7: 106.9 | T7: 106 | U7: 106.8 | V7: 100.4 | W7: 106 | X7: 105.2 | Y7: 104.5 | Z7: 104.2 | AA7: 103.6 | AB7: 103.9 | AC7: 104.5 | AD7: 104.4 | AE7: 105.3 | AF7: =SUM($E7:$Q7) -> 1384.2 | AG7: =SUM($S7:$U7) -> 319.7 | AH7: =SUM(V7,X7,AB7) -> 309.5 | AI7: =SUM(Y7,AC7) -> 209 | AJ7: =SUM(W7,Z7) -> 210.2 | AK7: =SUM(R7,AA7,AD7) -> 313.7
A8: Rural | B8: 2013 | C8: March | D8: =B8&" "&C8 -> 2013 March | E8: 110.2 | F8: 108.8 | G8: 109.9 | H8: 105.6 | I8: 106.2 | J8: 105.7 | K8: 101.4 | L8: 105.7 | M8: 105 | N8: 103.3 | O8: 105.6 | P8: 108.2 | Q8: 106.6 | R8: 106.5 | S8: 107.6 | T8: 106.8 | U8: 107.5 | V8: 100.4 | W8: 106.1 | X8: 105.6 | Y8: 104.7 | Z8: 104.6 | AA8: 104 | AB8: 104.3 | AC8: 104.3 | AD8: 104.6 | AE8: 106 | AF8: =SUM($E8:$Q8) -> 1382.2 | AG8: =SUM($S8:$U8) -> 321.9 | AH8: =SUM(V8,X8,AB8) -> 310.3 | AI8: =SUM(Y8,AC8) -> 209 | AJ8: =SUM(W8,Z8) -> 210.7 | AK8: =SUM(R8,AA8,AD8) -> 315.1
A9: Urban | B9: 2013 | C9: March | D9: =B9&" "&C9 -> 2013 March | E9: 113.9 | F9: 111.4 | G9: 113.2 | H9: 104.3 | I9: 102.7 | J9: 104.9 | K9: 103.8 | L9: 103.5 | M9: 102.6 | N9: 102.4 | O9: 107 | P9: 109.8 | Q9: 107.3 | R9: 106.8 | S9: 107.2 | T9: 106 | U9: 107 | V9: 100.4 | W9: 106 | X9: 105.7 | Y9: 105.2 | Z9: 105.5 | AA9: 103.5 | AB9: 103.8 | AC9: 104.2 | AD9: 104.9 | AE9: 105 | AF9: =SUM($E9:$Q9) -> 1386.8 | AG9: =SUM($S9:$U9) -> 320.2 | AH9: =SUM(V9,X9,AB9) -> 309.9 | AI9: =SUM(Y9,AC9) -> 209.4 | AJ9: =SUM(W9,Z9) -> 211.5 | AK9: =SUM(R9,AA9,AD9) -> 315.2
A10: Rural+Urban | B10: 2013 | C10: March | D10: =B10&" "&C10 -> 2013 March | E10: 111.4 | F10: 109.7 | G10: 111.2 | H10: 105.1 | I10: 104.9 | J10: 105.3 | K10: 102.2 | L10: 105 | M10: 104.2 | N10: 103 | O10: 106.2 | P10: 108.9 | Q10: 106.9 | R10: 106.6 | S10: 107.4 | T10: 106.5 | U10: 107.3 | V10: 100.4 | W10: 106.1 | X10: 105.6 | Y10: 104.9 | Z10: 105.1 | AA10: 103.7 | AB10: 104 | AC10: 104.3 | AD10: 104.7 | AE10: 105.5 | AF10: =SUM($E10:$Q10) -> 1384 | AG10: =SUM($S10:$U10) -> 321.2 | AH10: =SUM(V10,X10,AB10) -> 310 | AI10: =SUM(Y10,AC10) -> 209.2 | AJ10: =SUM(W10,Z10) -> 211.2 | AK10: =SUM(R10,AA10,AD10) -> 315
A11: Rural | B11: 2013 | C11: April | D11: =B11&" "&C11 -> 2013 April | E11: 110.2 | F11: 109.5 | G11: 106.9 | H11: 106.3 | I11: 105.7 | J11: 108.3 | K11: 103.4 | L11: 105.7 | M11: 104.2 | N11: 103.2 | O11: 106.5 | P11: 108.8 | Q11: 107.1 | R11: 107.1 | S11: 108.1 | T11: 107.4 | U11: 108 | V11: 100.5 | W11: 106.5 | X11: 106.1 | Y11: 105.1 | Z11: 104.4 | AA11: 104.5 | AB11: 104.8 | AC11: 102.7 | AD11: 104.6 | AE11: 106.4 | AF11: =SUM($E11:$Q11) -> 1385.8 | AG11: =SUM($S11:$U11) -> 323.5 | AH11: =SUM(V11,X11,AB11) -> 311.4 | AI11: =SUM(Y11,AC11) -> 207.8 | AJ11: =SUM(W11,Z11) -> 210.9 | AK11: =SUM(R11,AA11,AD11) -> 316.2
A12: Urban | B12: 2013 | C12: April | D12: =B12&" "&C12 -> 2013 April | E12: 114.6 | F12: 113.4 | G12: 106 | H12: 104.7 | I12: 102.1 | J12: 109.5 | K12: 109.7 | L12: 104.6 | M12: 102 | N12: 103.5 | O12: 108.2 | P12: 110.6 | Q12: 108.8 | R12: 108.5 | S12: 107.9 | T12: 106.4 | U12: 107.7 | V12: 100.5 | W12: 106.4 | X12: 106.5 | Y12: 105.7 | Z12: 105 | AA12: 104 | AB12: 105.2 | AC12: 103.2 | AD12: 105.1 | AE12: 105.7 | AF12: =SUM($E12:$Q12) -> 1397.7 | AG12: =SUM($S12:$U12) -> 322 | AH12: =SUM(V12,X12,AB12) -> 312.2 | AI12: =SUM(Y12,AC12) -> 208.9 | AJ12: =SUM(W12,Z12) -> 211.4 | AK12: =SUM(R12,AA12,AD12) -> 317.6
A13: Rural+Urban | B13: 2013 | C13: April | D13: =B13&" "&C13 -> 2013 April | E13: 111.6 | F13: 110.9 | G13: 106.6 | H13: 105.7 | I13: 104.4 | J13: 108.9 | K13: 105.5 | L13: 105.3 | M13: 103.5 | N13: 103.3 | O13: 107.2 | P13: 109.6 | Q13: 107.7 | R13: 107.5 | S13: 108 | T13: 107 | U13: 107.9 | V13: 100.5 | W13: 106.5 | X13: 106.3 | Y13: 105.3 | Z13: 104.7 | AA13: 104.2 | AB13: 105 | AC13: 102.9 | AD13: 104.8 | AE13: 106.1 | AF13: =SUM($E13:$Q13) -> 1390.2 | AG13: =SUM($S13:$U13) -> 322.9 | AH13: =SUM(V13,X13,AB13) -> 311.8 | AI13: =SUM(Y13,AC13) -> 208.2 | AJ13: =SUM(W13,Z13) -> 211.2 | AK13: =SUM(R13,AA13,AD13) -> 316.5
... A226: Rural+Urban | B226: 2019 | C226: March | D226: =B226&" "&C226 -> 2019 March | E226: 137.8 | F226: 153 | G226: 140.3 | H226: 142.3 | I226: 122 | J226: 137.6 | K226: 132.6 | L226: 121.8 | M226: 109 | N226: 139.5 | O226: 133.7 | P226: 155.2 | Q226: 138.1 | R226: 163.5 | S226: 147.9 | T226: 139.9 | U226: 146.7 | V226: 149 | W226: 139.7 | X226: 143.8 | Y226: 146.2 | Z226: 124.6 | AA226: 137.7 | AB226: 150.3 | AC226: 133.4 | AD226: 137.7 | AE226: 140.4 | AF226: =SUM($E226:$Q226) -> 1762.9 | AG226: =SUM($S226:$U226) -> 434.5 | AH226: =SUM(V226,X226,AB226) -> 443.1 | AI226: =SUM(Y226,AC226) -> 279.6 | AJ226: =SUM(W226,Z226) -> 264.3 | AK226: =SUM(R226,AA226,AD226) -> 438.9
A227: Rural | B227: 2019 | C227: April | D227: =B227&" "&C227 -> 2019 April | E227: =AVERAGE(E224,E221,E218,E215,E212,E209) -> 137.3 | F227: =AVERAGE(F224,F221,F218,F215,F212,F209) -> 151.65 | G227: =AVERAGE(G224,G221,G218,G215,G212,G209) -> 137.45 | H227: =AVERAGE(H224,H221,H218,H215,H212,H209) -> 142.26667 | I227: =AVERAGE(I224,I221,I218,I215,I212,I209) -> 123.76667 | J227: =AVERAGE(J224,J221,J218,J215,J212,J209) -> 139.33333 | K227: =AVERAGE(K224,K221,K218,K215,K212,K209) -> 136.71667 | L227: =AVERAGE(L224,L221,L218,L215,L212,L209) -> 121.4 | ... U227: =AVERAGE(U224,U221,U218,U215,U212,U209) -> 150.21667 | V227: 148.4 | W227: =AVERAGE(W224,W221,W218,W215,W212,W209) -> 147.81667 | X227: =AVERAGE(X224,X221,X218,X215,X212,X209) -> 149.2 | Y227: =AVERAGE(Y224,Y221,Y218,Y215,Y212,Y209) -> 148.28333 | Z227: =AVERAGE(Z224,Z221,Z218,Z215,Z212,Z209) -> 129.61667 | AA227: =AVERAGE(AA224,AA221,AA218,AA215,AA212,AA209) -> 142.76667 | AB227: =AVERAGE(AB224,AB221,AB218,AB215,AB212,AB209) -> 153.25 | AC227: =AVERAGE(AC224,AC221,AC218,AC215,AC212,AC209) -> 133.85 | AD227: =AVERAGE(AD224,AD221,AD218,AD215,AD212,AD209) -> 141.3 | AE227: =AVERAGE(AE224,AE221,AE218,AE215,AE212,AE209) -> 141.61667 | AF227: =SUM($E227:$Q227) -> 1770.5667 | AG227: =SUM($S227:$U227) -> 446.73333 | AH227: =SUM(V227,X227,AB227) -> 450.85 | AI227: =SUM(Y227,AC227) -> 282.13333 | AJ227: =SUM(W227,Z227) -> 277.43333 | AK227: =SUM(R227,AA227,AD227) -> 446.11667
A228: Urban | B228: 2019 | C228: April | D228: =B228&" "&C228 -> 2019 April | E228: =AVERAGE(E225,E222,E219) -> 139.13333 | F228: =AVERAGE(F225,F222,F219) -> 150.2 | G228: =AVERAGE(G225,G222,G219) -> 143.9 | H228: =AVERAGE(H225,H222,H219) -> 141.76667 | I228: =AVERAGE(I225,I222,I219) -> 118.3 | J228: =AVERAGE(J225,J222,J219) -> 137.2 | K228: =AVERAGE(K225,K222,K219) -> 134.43333 | L228: =AVERAGE(L225,L222,L219) -> 119.6 | ... U228: =AVERAGE(U225,U222,U219) -> 141.36667 | V228: 148.4 | W228: =AVERAGE(W225,W222,W219) -> 128.16667 | X228: =AVERAGE(X225,X222,X219) -> 136.56667 | Y228: =AVERAGE(Y225,Y222,Y219) -> 138.5 | Z228: =AVERAGE(Z225,Z222,Z219) -> 119.23333 | AA228: =AVERAGE(AA225,AA222,AA219) -> 132.36667 | AB228: =AVERAGE(AB225,AB222,AB219) -> 146.63333 | AC228: =AVERAGE(AC225,AC222,AC219) -> 132.4 | AD228: =AVERAGE(AD225,AD222,AD219) -> 132.33333 | AE228: =AVERAGE(AE225,AE222,AE219) -> 138.7 | AF228: =SUM($E228:$Q228) -> 1755.7 | AG228: =SUM($S228:$U228) -> 415.43333 | AH228: =SUM(V228,X228,AB228) -> 431.6 | AI228: =SUM(Y228,AC228) -> 270.9 | AJ228: =SUM(W228,Z228) -> 247.4 | AK228: =SUM(R228,AA228,AD228) -> 429.66667
A229: Rural+Urban | B229: 2019 | C229: April | D229: =B229&" "&C229 -> 2019 April | E229: =AVERAGE(E226,E223,E220) -> 137.5 | F229: =AVERAGE(F226,F223,F220) -> 152.13333 | G229: =AVERAGE(G226,G223,G220) -> 140.66667 | H229: =AVERAGE(H226,H223,H220) -> 142.2 | I229: =AVERAGE(I226,I223,I220) -> 121.93333 | J229: =AVERAGE(J226,J223,J220) -> 136.46667 | K229: =AVERAGE(K226,K223,K220) -> 131.2 | L229: =AVERAGE(L226,L223,L220) -> 121.03333 | ... U229: =AVERAGE(U226,U223,U220) -> 146.53333 | V229: 148.4 | W229: =AVERAGE(W226,W223,W220) -> 139.2 | X229: =AVERAGE(X226,X223,X220) -> 143.7 | Y229: =AVERAGE(Y226,Y223,Y220) -> 145.63333 | Z229: =AVERAGE(Z226,Z223,Z220) -> 123.93333 | AA229: =AVERAGE(AA226,AA223,AA220) -> 137.16667 | AB229: =AVERAGE(AB226,AB223,AB220) -> 150.26667 | AC229: =AVERAGE(AC226,AC223,AC220) -> 133.43333 | AD229: =AVERAGE(AD226,AD223,AD220) -> 137.33333 | AE229: =AVERAGE(AE226,AE223,AE220) -> 139.96667 | AF229: =SUM($E229:$Q229) -> 1757.8 | AG229: =SUM($S229:$U229) -> 433.8 | AH229: =SUM(V229,X229,AB229) -> 442.36667 | AI229: =SUM(Y229,AC229) -> 279.06667 | AJ229: =SUM(W229,Z229) -> 263.13333 | AK229: =SUM(R229,AA229,AD229) -> 437.86667
A230: Rural | B230: 2019 | C230: May | D230: =B230&" "&C230 -> 2019 May | E230: 137.4 | F230: 159.5 | G230: 134.5 | H230: 142.6 | I230: 124 | J230: 143.7 | K230: 133.4 | L230: 125.1 | M230: 109.3 | N230: 139.3 | O230: 137.7 | P230: 156.4 | Q230: 139.2 | R230: 163.3 | S230: 151.3 | T230: 146.6 | U230: 150.7 | V230: 150.1 | W230: 146.9 | X230: 149.5 | Y230: 151.3 | Z230: 130.2 | AA230: 145.9 | AB230: 156.7 | AC230: 133.9 | AD230: 142.9 | AE230: 142.4 | AF230: =SUM($E230:$Q230) -> 1782.1 | AG230: =SUM($S230:$U230) -> 448.6 | AH230: =SUM(V230,X230,AB230) -> 456.3 | AI230: =SUM(Y230,AC230) -> 285.2 | AJ230: =SUM(W230,Z230) -> 277.1 | AK230: =SUM(R230,AA230,AD230) -> 452.1
A231: Urban | B231: 2019 | C231: May | D231: =B231&" "&C231 -> 2019 May | E231: 140.4 | F231: 156.7 | G231: 138.3 | H231: 142.4 | I231: 118.6 | J231: 149.7 | K231: 161.6 | L231: 124.4 | M231: 111.2 | N231: 141 | O231: 128.9 | P231: 154.5 | Q231: 143.8 | R231: 166.2 | S231: 144 | T231: 131.7 | U231: 142.2 | V231: 150.1 | W231: 129.4 | X231: 137.2 | Y231: 139.8 | Z231: 120.1 | AA231: 134 | AB231: 148 | AC231: 132.6 | AD231: 133.3 | AE231: 141.5 | AF231: =SUM($E231:$Q231) -> 1811.5 | AG231: =SUM($S231:$U231) -> 417.9 | AH231: =SUM(V231,X231,AB231) -> 435.3 | AI231: =SUM(Y231,AC231) -> 272.4 | AJ231: =SUM(W231,Z231) -> 249.5 | AK231: =SUM(R231,AA231,AD231) -> 433.5
A232: Rural+Urban | B232: 2019 | C232: May | D232: =B232&" "&C232 -> 2019 May | E232: 138.3 | F232: 158.5 | G232: 136 | H232: 142.5 | I232: 122 | J232: 146.5 | K232: 143 | L232: 124.9 | M232: 109.9 | N232: 139.9 | O232: 134 | P232: 155.5 | Q232: 140.9 | R232: 164.1 | S232: 148.4 | T232: 140.4 | U232: 147.3 | V232: 150.1 | W232: 140.3 | X232: 143.7 | Y232: 146.9 | Z232: 124.9 | AA232: 139.2 | AB232: 151.6 | AC232: 133.4 | AD232: 138.2 | AE232: 142 | AF232: =SUM($E232:$Q232) -> 1791.9 | AG232: =SUM($S232:$U232) -> 436.1 | AH232: =SUM(V232,X232,AB232) -> 445.4 | AI232: =SUM(Y232,AC232) -> 280.3 | AJ232: =SUM(W232,Z232) -> 265.2 | AK232: =SUM(R232,AA232,AD232) -> 441.5
A233: Rural | B233: 2019 | C233: June | D233: =B233&" "&C233 -> 2019 June | E233: 137.8 | F233: 163.5 | G233: 136.2 | H233: 143.2 | I233: 124.3 | J233: 143.3 | K233: 140.6 | L233: 128.7 | M233: 110.6 | N233: 140.4 | O233: 138 | P233: 156.6 | Q233: 141 | R233: 164.2 | S233: 151.4 | T233: 146.5 | U233: 150.7 | V233: 149.4 | W233: 147.8 | X233: 149.6 | Y233: 151.7 | Z233: 130.2 | AA233: 146.4 | AB233: 157.7 | AC233: 134.8 | AD233: 143.3 | AE233: 143.6 | AF233: =SUM($E233:$Q233) -> 1804.2 | AG233: =SUM($S233:$U233) -> 448.6 | AH233: =SUM(V233,X233,AB233) -> 456.7 | AI233: =SUM(Y233,AC233) -> 286.5 | AJ233: =SUM(W233,Z233) -> 278 | AK233: =SUM(R233,AA233,AD233) -> 453.9
A234: Urban | B234: 2019 | C234: June | D234: =B234&" "&C234 -> 2019 June | E234: 140.7 | F234: 159.6 | G234: 140.4 | H234: 143.4 | I234: 118.6 | J234: 150.9 | K234: 169.8 | L234: 127.4 | M234: 111.8 | N234: 141 | O234: 129 | P234: 155.1 | Q234: 145.6 | R234: 166.7 | S234: 144.3 | T234: 131.7 | U234: 142.4 | V234: 149.4 | W234: 130.5 | X234: 137.4 | Y234: 140.3 | Z234: 119.6 | AA234: 134.3 | AB234: 148.9 | AC234: 133.7 | AD234: 133.6 | AE234: 142.1 | AF234: =SUM($E234:$Q234) -> 1833.3 | AG234: =SUM($S234:$U234) -> 418.4 | AH234: =SUM(V234,X234,AB234) -> 435.7 | AI234: =SUM(Y234,AC234) -> 274 | AJ234: =SUM(W234,Z234) -> 250.1 | AK234: =SUM(R234,AA234,AD234) -> 434.6
A235: Rural+Urban | B235: 2019 | C235: June | D235: =B235&" "&C235 -> 2019 June | E235: 138.7 | F235: 162.1 | G235: 137.8 | H235: 143.3 | I235: 122.2 | J235: 146.8 | K235: 150.5 | L235: 128.3 | M235: 111 | N235: 140.6 | O235: 134.2 | P235: 155.9 | Q235: 142.7 | R235: 164.9 | S235: 148.6 | T235: 140.4 | U235: 147.4 | V235: 149.4 | W235: 141.2 | X235: 143.8 | Y235: 147.4 | Z235: 124.6 | AA235: 139.6 | AB235: 152.5 | AC235: 134.3 | AD235: 138.6 | AE235: 142.9 | AF235: =SUM($E235:$Q235) -> 1814.1 | AG235: =SUM($S235:$U235) -> 436.4 | AH235: =SUM(V235,X235,AB235) -> 445.7 | AI235: =SUM(Y235,AC235) -> 281.7 | AJ235: =SUM(W235,Z235) -> 265.8 | AK235: =SUM(R235,AA235,AD235) -> 443.1
A236: Rural | B236: 2019 | C236: July | D236: =B236&" "&C236 -> 2019 July | E236: 138.4 | F236: 164 | G236: 138.4 | H236: 143.9 | I236: 124.4 | J236: 146.4 | K236: 150.1 | L236: 130.6 | M236: 110.8 | N236: 141.7 | O236: 138.5 | P236: 156.7 | Q236: 143 | R236: 164.5 | S236: 151.6 | T236: 146.6 | U236: 150.9 | V236: 150.6 | W236: 146.8 | X236: 150 | Y236: 152.2 | Z236: 131.2 | AA236: 147.5 | AB236: 159.1 | AC236: 136.1 | AD236: 144.2 | AE236: 144.9 | AF236: =SUM($E236:$Q236) -> 1826.9 | AG236: =SUM($S236:$U236) -> 449.1 | AH236: =SUM(V236,X236,AB236) -> 459.7 | AI236: =SUM(Y236,AC236) -> 288.3 | AJ236: =SUM(W236,Z236) -> 278 | AK236: =SUM(R236,AA236,AD236) -> 456.2
A237: Urban | B237: 2019 | C237: July | D237: =B237&" "&C237 -> 2019 July | E237: 141.4 | F237: 160.2 | G237: 142.5 | H237: 144.1 | I237: 119.3 | J237: 154.7 | K237: 180.1 | L237: 128.9 | M237: 111.8 | N237: 141.6 | O237: 129.5 | P237: 155.6 | Q237: 147.7 | R237: 167.2 | S237: 144.7 | T237: 131.9 | U237: 142.7 | V237: 150.6 | W237: 127 | X237: 137.7 | Y237: 140.8 | Z237: 120.6 | AA237: 135 | AB237: 150.4 | AC237: 135.1 | AD237: 134.5 | AE237: 143.3 | AF237: =SUM($E237:$Q237) -> 1857.4 | AG237: =SUM($S237:$U237) -> 419.3 | AH237: =SUM(V237,X237,AB237) -> 438.7 | AI237: =SUM(Y237,AC237) -> 275.9 | AJ237: =SUM(W237,Z237) -> 247.6 | AK237: =SUM(R237,AA237,AD237) -> 436.7
A238: Rural+Urban | B238: 2019 | C238: July | D238: =B238&" "&C238 -> 2019 July | E238: 139.3 | F238: 162.7 | G238: 140 | H238: 144 | I238: 122.5 | J238: 150.3 | K238: 160.3 | L238: 130 | M238: 111.1 | N238: 141.7 | O238: 134.7 | P238: 156.2 | Q238: 144.7 | R238: 165.2 | S238: 148.9 | T238: 140.5 | U238: 147.6 | V238: 150.6 | W238: 139.3 | X238: 144.2 | Y238: 147.9 | Z238: 125.6 | AA238: 140.5 | AB238: 154 | AC238: 135.7 | AD238: 139.5 | AE238: 144.2 | AF238: =SUM($E238:$Q238) -> 1837.5 | AG238: =SUM($S238:$U238) -> 437 | AH238: =SUM(V238,X238,AB238) -> 448.8 | AI238: =SUM(Y238,AC238) -> 283.6 | AJ238: =SUM(W238,Z238) -> 264.9 | AK238: =SUM(R238,AA238,AD238) -> 445.2
A239: Rural | B239: 2019 | C239: August | D239: =B239&" "&C239 -> 2019 August | E239: 139.2 | F239: 161.9 | G239: 137.1 | H239: 144.6 | I239: 124.7 | J239: 145.5 | K239: 156.2 | L239: 131.5 | M239: 111.7 | N239: 142.7 | O239: 138.5 | P239: 156.9 | Q239: 144 | R239: 165.1 | S239: 151.8 | T239: 146.6 | U239: 151.1 | V239: 151.6 | W239: 146.4 | X239: 150.2 | Y239: 152.7 | Z239: 131.4 | AA239: 148 | AB239: 159.7 | AC239: 138.8 | AD239: 144.9 | AE239: 145.7 | AF239: =SUM($E239:$Q239) -> 1834.5 | AG239: =SUM($S239:$U239) -> 449.5 | AH239: =SUM(V239,X239,AB239) -> 461.5 | AI239: =SUM(Y239,AC239) -> 291.5 | AJ239: =SUM(W239,Z239) -> 277.8 | AK239: =SUM(R239,AA239,AD239) -> 458
A240: Urban | B240: 2019 | C240: August | D240: =B240&" "&C240 -> 2019 August | E240: 142.1 | F240: 158.3 | G240: 140.8 | H240: 144.9 | I240: 119.9 | J240: 153.9 | K240: 189.1 | L240: 129.8 | M240: 112.7 | N240: 142.5 | O240: 129.8 | P240: 156.2 | Q240: 149.1 | R240: 167.9 | S240: 145 | T240: 132.2 | U240: 143 | V240: 151.6 | W240: 125.5 | X240: 138.1 | Y240: 141.5 | Z240: 120.8 | AA240: 135.4 | AB240: 151.5 | AC240: 137.8 | AD240: 135.3 | AE240: 144.2 | AF240: =SUM($E240:$Q240) -> 1869.1 | AG240: =SUM($S240:$U240) -> 420.2 | AH240: =SUM(V240,X240,AB240) -> 441.2 | AI240: =SUM(Y240,AC240) -> 279.3 | AJ240: =SUM(W240,Z240) -> 246.3 | AK240: =SUM(R240,AA240,AD240) -> 438.6
A241: Rural+Urban | B241: 2019 | C241: August | D241: =B241&" "&C241 -> 2019 August | E241: 140.1 | F241: 160.6 | G241: 138.5 | H241: 144.7 | I241: 122.9 | J241: 149.4 | K241: 167.4 | L241: 130.9 | M241: 112 | N241: 142.6 | O241: 134.9 | P241: 156.6 | Q241: 145.9 | R241: 165.8 | S241: 149.1 | T241: 140.6 | U241: 147.9 | V241: 151.6 | W241: 138.5 | X241: 144.5 | Y241: 148.5 | Z241: 125.8 | AA241: 140.9 | AB241: 154.9 | AC241: 138.4 | AD241: 140.2 | AE241: 145 | AF241: =SUM($E241:$Q241) -> 1846.5 | AG241: =SUM($S241:$U241) -> 437.6 | AH241: =SUM(V241,X241,AB241) -> 451 | AI241: =SUM(Y241,AC241) -> 286.9 | AJ241: =SUM(W241,Z241) -> 264.3 | AK241: =SUM(R241,AA241,AD241) -> 446.9
... A262: Rural+Urban | B262: 2020 | C262: March | D262: =B262&" "&C262 -> 2020 March | E262: 145.1 | F262: 167 | G262: 148.1 | H262: 151.5 | I262: 131.2 | J262: 142.5 | K262: 157.3 | L262: 141.1 | M262: 113.2 | N262: 153.2 | O262: 136.7 | P262: 159.6 | Q262: 148.9 | R262: 171.2 | S262: 151.2 | T262: 141.9 | U262: 149.8 | V262: 154.5 | W262: 148.9 | X262: 146.4 | Y262: 152.3 | Z262: 129.9 | AA262: 143.7 | AB262: 156.1 | AC262: 145.2 | AD262: 143.8 | AE262: 148.6 | AF262: =SUM($E262:$Q262) -> 1895.4 | AG262: =SUM($S262:$U262) -> 442.9 | AH262: =SUM(V262,X262,AB262) -> 457 | AI262: =SUM(Y262,AC262) -> 297.5 | AJ262: =SUM(W262,Z262) -> 278.8 | AK262: =SUM(R262,AA262,AD262) -> 458.7
A263: Rural | B263: 2020 | C263: April | D263: =B263&" "&C263 -> 2020 April | E263: 147.2 | F263: =AVERAGE(F260,F257,F254) -> 167.2 | G263: 146.9 | H263: 155.6 | I263: 137.1 | J263: 147.3 | K263: 162.7 | L263: 150.2 | M263: 119.8 | N263: 158.7 | O263: 139.2 | P263: =AVERAGE(P260,P257,P254) -> 159.3 | Q263: 150.1 | R263: =AVERAGE(R260,R257,R254) -> 169.5 | S263: =AVERAGE(S260,S257,S254) -> 153.06667 | T263: =AVERAGE(T260,T257,T254) -> 147.5 | U263: =AVERAGE(U260,U257,U254) -> 152.3 | V263: 155.6 | W263: 148.4 | X263: =AVERAGE(X260,X257,X254) -> 151.66667 | Y263: 154.3 | Z263: =AVERAGE(Z260,Z257,Z254) -> 136.03333 | AA263: =AVERAGE(AA260,AA257,AA254) -> 150.56667 | AB263: =AVERAGE(AB260,AB257,AB254) -> 161.6 | AC263: =AVERAGE(AC260,AC257,AC254) -> 143.66667 | AD263: =AVERAGE(AD260,AD257,AD254) -> 148.36667 | AE263: =AVERAGE(AE260,AE257,AE254) -> 150.7 | AF263: =SUM($E263:$Q263) -> 1941.3 | AG263: =SUM($S263:$U263) -> 452.86667 | AH263: =SUM(V263,X263,AB263) -> 468.86667 | AI263: =SUM(Y263,AC263) -> 297.96667 | AJ263: =SUM(W263,Z263) -> 284.43333 | AK263: =SUM(R263,AA263,AD263) -> 468.43333
A264: Urban | B264: 2020 | C264: April | D264: =B264&" "&C264 -> 2020 April | E264: 151.8 | F264: =AVERAGE(F261,F258,F255) -> 167.56667 | G264: 151.9 | H264: 155.5 | I264: 131.6 | J264: 152.9 | K264: 180 | L264: 150.8 | M264: 121.2 | N264: 154 | O264: 133.5 | P264: =AVERAGE(P261,P258,P255) -> 158.86667 | Q264: 153.5 | R264: =AVERAGE(R261,R258,R255) -> 172.03333 | S264: =AVERAGE(S261,S258,S255) -> 147.33333 | T264: =AVERAGE(T261,T258,T255) -> 133.5 | U264: =AVERAGE(U261,U258,U255) -> 145.23333 | V264: 155.6 | W264: 137.1 | X264: =AVERAGE(X261,X258,X255) -> 140.43333 | Y264: 144.8 | Z264: =AVERAGE(Z261,Z258,Z255) -> 125.3 | AA264: =AVERAGE(AA261,AA258,AA255) -> 137.6 | AB264: =AVERAGE(AB261,AB258,AB255) -> 152.26667 | AC264: =AVERAGE(AC261,AC258,AC255) -> 143.63333 | AD264: =AVERAGE(AD261,AD258,AD255) -> 138.5 | AE264: =AVERAGE(AE261,AE258,AE255) -> 147.73333 | AF264: =SUM($E264:$Q264) -> 1963.1333 | AG264: =SUM($S264:$U264) -> 426.06667 | AH264: =SUM(V264,X264,AB264) -> 448.3 | AI264: =SUM(Y264,AC264) -> 288.43333 | AJ264: =SUM(W264,Z264) -> 262.4 | AK264: =SUM(R264,AA264,AD264) -> 448.13333
A265: Rural+Urban | B265: 2020 | C265: April | D265: =B265&" "&C265 -> 2020 April | E265: 148.7 | F265: =AVERAGE(F262,F259,F256) -> 167.3 | G265: 148.8 | H265: 155.6 | I265: 135.1 | J265: 149.9 | K265: 168.6 | L265: 150.4 | M265: 120.3 | N265: 157.1 | O265: 136.8 | P265: =AVERAGE(P262,P259,P256) -> 159.1 | Q265: 151.4 | R265: =AVERAGE(R262,R259,R256) -> 170.16667 | S265: =AVERAGE(S262,S259,S256) -> 150.83333 | T265: =AVERAGE(T262,T259,T256) -> 141.7 | U265: =AVERAGE(U262,U259,U256) -> 149.5 | V265: 155.6 | W265: 144.1 | X265: =AVERAGE(X262,X259,X256) -> 146.33333 | Y265: 150.7 | Z265: =AVERAGE(Z262,Z259,Z256) -> 130.36667 | AA265: =AVERAGE(AA262,AA259,AA256) -> 143.23333 | AB265: =AVERAGE(AB262,AB259,AB256) -> 156.13333 | AC265: =AVERAGE(AC262,AC259,AC256) -> 143.63333 | AD265: =AVERAGE(AD262,AD259,AD256) -> 143.6 | AE265: =AVERAGE(AE262,AE259,AE256) -> 149.3 | AF265: =SUM($E265:$Q265) -> 1949.1 | AG265: =SUM($S265:$U265) -> 442.03333 | AH265: =SUM(V265,X265,AB265) -> 458.06667 | AI265: =SUM(Y265,AC265) -> 294.33333 | AJ265: =SUM(W265,Z265) -> 274.46667 | AK265: =SUM(R265,AA265,AD265) -> 457
A266: Rural | B266: 2020 | C266: May | D266: =B266&" "&C266 -> 2020 May | E266: =AVERAGE(E263,E260,E257) -> 145.26667 | F266: =AVERAGE(F263,F260,F257) -> 167.16667 | G266: =AVERAGE(G263,G260,G257) -> 148.46667 | H266: =AVERAGE(H263,H260,H257) -> 152.73333 | I266: =AVERAGE(I263,I260,I257) -> 134.7 | J266: =AVERAGE(J263,J260,J257) -> 143.26667 | K266: =AVERAGE(K263,K260,K257) -> 160.03333 | L266: =AVERAGE(L263,L260,L257) -> 144.6 | ... U266: =AVERAGE(U263,U260,U257) -> 152.36667 | V266: 155.6 | W266: =AVERAGE(W265,W264,W263) -> 143.2 | X266: =AVERAGE(X263,X260,X257) -> 151.65556 | Y266: =AVERAGE(Y263,Y260,Y257) -> 155.73333 | Z266: =AVERAGE(Z263,Z260,Z257) -> 135.94444 | AA266: =AVERAGE(AA263,AA260,AA257) -> 150.72222 | AB266: =AVERAGE(AB263,AB260,AB257) -> 161.56667 | AC266: =AVERAGE(AC263,AC260,AC257) -> 144.05556 | AD266: =AVERAGE(AD263,AD260,AD257) -> 148.45556 | AE266: =AVERAGE(AE263,AE260,AE257) -> 150.3 | AF266: =SUM($E266:$Q266) -> 1915.2333 | AG266: =SUM($S266:$U266) -> 453.05556 | AH266: =SUM(V266,X266,AB266) -> 468.82222 | AI266: =SUM(Y266,AC266) -> 299.78889 | AJ266: =SUM(W266,Z266) -> 279.14444 | AK266: =SUM(R266,AA266,AD266) -> 468.97778
A267: Urban | B267: 2020 | C267: May | D267: =B267&" "&C267 -> 2020 May | E267: =AVERAGE(E264,E261,E258) -> 148.16667 | F267: =AVERAGE(F264,F261,F258) -> 167.55556 | G267: =AVERAGE(G264,G261,G258) -> 151.3 | H267: =AVERAGE(H264,H261,H258) -> 152.43333 | I267: =AVERAGE(I264,I261,I258) -> 128.83333 | J267: =AVERAGE(J264,J261,J258) -> 146.43333 | K267: =AVERAGE(K264,K261,K258) -> 176.23333 | L267: =AVERAGE(L264,L261,L258) -> 143.36667 | ... U267: =AVERAGE(U264,U261,U258) -> 145.34444 | V267: 155.6 | W267: =AVERAGE(W264,W261,W258) -> 139.13333 | X267: =AVERAGE(X264,X261,X258) -> 140.54444 | Y267: =AVERAGE(Y264,Y261,Y258) -> 144.73333 | Z267: =AVERAGE(Z264,Z261,Z258) -> 125.03333 | AA267: =AVERAGE(AA264,AA261,AA258) -> 137.73333 | AB267: =AVERAGE(AB264,AB261,AB258) -> 152.32222 | AC267: =AVERAGE(AC264,AC261,AC258) -> 144.14444 | AD267: =AVERAGE(AD264,AD261,AD258) -> 138.53333 | AE267: =AVERAGE(AE264,AE261,AE258) -> 147.57778 | AF267: =SUM($E267:$Q267) -> 1926.0778 | AG267: =SUM($S267:$U267) -> 426.38889 | AH267: =SUM(V267,X267,AB267) -> 448.46667 | AI267: =SUM(Y267,AC267) -> 288.87778 | AJ267: =SUM(W267,Z267) -> 264.16667 | AK267: =SUM(R267,AA267,AD267) -> 448.71111
A268: Rural+Urban | B268: 2020 | C268: May | D268: =B268&" "&C268 -> 2020 May | E268: =AVERAGE(E265,E262,E259) -> 146.2 | F268: =AVERAGE(F265,F262,F259) -> 167.26667 | G268: =AVERAGE(G265,G262,G259) -> 149.56667 | H268: =AVERAGE(H265,H262,H259) -> 152.63333 | I268: =AVERAGE(I265,I262,I259) -> 132.56667 | J268: =AVERAGE(J265,J262,J259) -> 144.73333 | K268: =AVERAGE(K265,K262,K259) -> 165.53333 | L268: =AVERAGE(L265,L262,L259) -> 144.2 | ... U268: =AVERAGE(U265,U262,U259) -> 149.6 | V268: 154.96667 | W268: =AVERAGE(W265,W262,W259) -> 146.73333 | X268: =AVERAGE(X265,X262,X259) -> 146.37778 | Y268: =AVERAGE(Y265,Y262,Y259) -> 151.56667 | Z268: =AVERAGE(Z265,Z262,Z259) -> 130.18889 | AA268: =AVERAGE(AA265,AA262,AA259) -> 143.37778 | AB268: =AVERAGE(AB265,AB262,AB259) -> 156.14444 | AC268: =AVERAGE(AC265,AC262,AC259) -> 144.07778 | AD268: =AVERAGE(AD265,AD262,AD259) -> 143.66667 | AE268: =AVERAGE(AE265,AE262,AE259) -> 149 | AF268: =SUM($E268:$Q268) -> 1918.7 | AG268: =SUM($S268:$U268) -> 442.31111 | AH268: =SUM(V268,X268,AB268) -> 457.48889 | AI268: =SUM(Y268,AC268) -> 295.64444 | AJ268: =SUM(W268,Z268) -> 276.92222 | AK268: =SUM(R268,AA268,AD268) -> 457.53333
A269: Rural | B269: 2020 | C269: June | D269: =B269&" "&C269 -> 2020 June | E269: 148.2 | F269: 190.3 | G269: 149.4 | H269: 153.3 | I269: 138.2 | J269: 143.2 | K269: 148.9 | L269: 150.3 | M269: 113.2 | N269: 159.8 | O269: 142.1 | P269: 161.8 | Q269: 152.3 | R269: 182.4 | S269: 154.7 | T269: 150 | U269: 154.1 | V269: 154.7 | W269: 144.9 | X269: 151.7 | Y269: 158.2 | Z269: 141.4 | AA269: 153.2 | AB269: 161.8 | AC269: 151.2 | AD269: 151.7 | AE269: 152.7 | AF269: =SUM($E269:$Q269) -> 1951 | AG269: =SUM($S269:$U269) -> 458.8 | AH269: =SUM(V269,X269,AB269) -> 468.2 | AI269: =SUM(Y269,AC269) -> 309.4 | AJ269: =SUM(W269,Z269) -> 286.3 | AK269: =SUM(R269,AA269,AD269) -> 487.3
A270: Urban | B270: 2020 | C270: June | D270: =B270&" "&C270 -> 2020 June | E270: 152.7 | F270: 197 | G270: 154.6 | H270: 153.4 | I270: 132.9 | J270: 151.8 | K270: 171.2 | L270: 152 | M270: 116.3 | N270: 158.8 | O270: 135.6 | P270: 161.7 | Q270: 157 | R270: 186.7 | S270: 149.1 | T270: 136.6 | U270: 147.2 | V270: 154.7 | W270: 137.1 | X270: 140.4 | Y270: 148.1 | Z270: 129.3 | AA270: 144.5 | AB270: 152.5 | AC270: 152.2 | AD270: 142 | AE270: 150.8 | AF270: =SUM($E270:$Q270) -> 1995 | AG270: =SUM($S270:$U270) -> 432.9 | AH270: =SUM(V270,X270,AB270) -> 447.6 | AI270: =SUM(Y270,AC270) -> 300.3 | AJ270: =SUM(W270,Z270) -> 266.4 | AK270: =SUM(R270,AA270,AD270) -> 473.2
A271: Rural+Urban | B271: 2020 | C271: June | D271: =B271&" "&C271 -> 2020 June | E271: 149.6 | F271: 192.7 | G271: 151.4 | H271: 153.3 | I271: 136.3 | J271: 147.2 | K271: 156.5 | L271: 150.9 | M271: 114.2 | N271: 159.5 | O271: 139.4 | P271: 161.8 | Q271: 154 | R271: 183.5 | S271: 152.5 | T271: 144.4 | U271: 151.4 | V271: 154.7 | W271: 141.9 | X271: 146.4 | Y271: 154.4 | Z271: 135 | AA271: 148.3 | AB271: 156.4 | AC271: 151.6 | AD271: 147 | AE271: 151.8 | AF271: =SUM($E271:$Q271) -> 1966.8 | AG271: =SUM($S271:$U271) -> 448.3 | AH271: =SUM(V271,X271,AB271) -> 457.5 | AI271: =SUM(Y271,AC271) -> 306 | AJ271: =SUM(W271,Z271) -> 276.9 | AK271: =SUM(R271,AA271,AD271) -> 478.8
A272: Rural | B272: 2020 | C272: July | D272: =B272&" "&C272 -> 2020 July | E272: 148.2 | F272: 190.3 | G272: 149.4 | H272: 153.3 | I272: 138.2 | J272: 143.2 | K272: 148.9 | L272: 150.3 | M272: 113.2 | N272: 159.8 | O272: 142.1 | P272: 161.8 | Q272: 152.3 | R272: 182.4 | S272: 154.7 | T272: 150 | U272: 154.1 | V272: 154.7 | W272: 144.9 | X272: 151.7 | Y272: 158.2 | Z272: 141.4 | AA272: 153.2 | AB272: 161.8 | AC272: 151.2 | AD272: 151.7 | AE272: 152.7 | AF272: =SUM($E272:$Q272) -> 1951 | AG272: =SUM($S272:$U272) -> 458.8 | AH272: =SUM(V272,X272,AB272) -> 468.2 | AI272: =SUM(Y272,AC272) -> 309.4 | AJ272: =SUM(W272,Z272) -> 286.3 | AK272: =SUM(R272,AA272,AD272) -> 487.3
...

Sheet 1. Broder_Cat _Contribution
B1: 1. Highest Contribution of Different Broader Categories Towards The CPI Basket
B3: Contribution of Broader Categories Based On Month
B4: Sector | C4: Year | D4: Month | E4: Food | F4: Clothing | G4: Essential | H4: Health | I4: Energy | J4: Lux
B5: Rural | C5: 2023 | D5: May | E5: {=INDEX('CPI Data'!AF:AF,MATCH(1,('CPI Data'!$A:$A=$B5)*('CPI Data'!$B:$B=$C5)*('CPI Data'!$C:$C=$D5),0))} -> 2290.7 | F5: {=INDEX('CPI Data'!AG:AG,MATCH(1,('CPI Data'!$A:$A=$B5)*('CPI Data'!$B:$B=$C5)*('CPI Data'!$C:$C=$D5),0))} -> 569.9 | G5: {=INDEX('CPI Data'!AH:AH,MATCH(1,('CPI Data'!$A:$A=$B5)*('CPI Data'!$B:$B=$C5)*('CPI Data'!$C:$C=$D5),0))} -> 535.7 | H5: {=INDEX('CPI Data'!AI:AI,MATCH(1,('CPI Data'!$A:$A=$B5)*('CPI Data'!$B:$B=$C5)*('CPI Data'!$C:$C=$D5),0))} -> 372.7 | I5: {=INDEX('CPI Data'!AJ:AJ,MATCH(1,('CPI Data'!$A:$A=$B5)*('CPI Data'!$B:$B=$C5)*('CPI Data'!$C:$C=$D5),0))} -> 352.2 | J5: {=INDEX('CPI Data'!AK:AK,MATCH(1,('CPI Data'!$A:$A=$B5)*('CPI Data'!$B:$B=$C5)*('CPI Data'!$C:$C=$D5),0))} -> 553.2
B6: Urban | C6: 2023 | D6: May | E6: {=INDEX('CPI Data'!AF:AF,MATCH(1,('CPI Data'!$A:$A=$B6)*('CPI Data'!$B:$B=$C6)*('CPI Data'!$C:$C=$D6),0))} -> 2335.1 | F6: {=INDEX('CPI Data'!AG:AG,MATCH(1,('CPI Data'!$A:$A=$B6)*('CPI Data'!$B:$B=$C6)*('CPI Data'!$C:$C=$D6),0))} -> 528.7 | G6: {=INDEX('CPI Data'!AH:AH,MATCH(1,('CPI Data'!$A:$A=$B6)*('CPI Data'!$B:$B=$C6)*('CPI Data'!$C:$C=$D6),0))} -> 520.5 | H6: {=INDEX('CPI Data'!AI:AI,MATCH(1,('CPI Data'!$A:$A=$B6)*('CPI Data'!$B:$B=$C6)*('CPI Data'!$C:$C=$D6),0))} -> 367.8 | I6: {=INDEX('CPI Data'!AJ:AJ,MATCH(1,('CPI Data'!$A:$A=$B6)*('CPI Data'!$B:$B=$C6)*('CPI Data'!$C:$C=$D6),0))} -> 343.8 | J6: {=INDEX('CPI Data'!AK:AK,MATCH(1,('CPI Data'!$A:$A=$B6)*('CPI Data'!$B:$B=$C6)*('CPI Data'!$C:$C=$D6),0))} -> 545
B7: Rural+Urban | C7: 2023 | D7: May | E7: {=INDEX('CPI Data'!AF:AF,MATCH(1,('CPI Data'!$A:$A=$B7)*('CPI Data'!$B:$B=$C7)*('CPI Data'!$C:$C=$D7),0))} -> 2306.9 | F7: {=INDEX('CPI Data'!AG:AG,MATCH(1,('CPI Data'!$A:$A=$B7)*('CPI Data'!$B:$B=$C7)*('CPI Data'!$C:$C=$D7),0))} -> 553.2 | G7: {=INDEX('CPI Data'!AH:AH,MATCH(1,('CPI Data'!$A:$A=$B7)*('CPI Data'!$B:$B=$C7)*('CPI Data'!$C:$C=$D7),0))} -> 527.9 | H7: {=INDEX('CPI Data'!AI:AI,MATCH(1,('CPI Data'!$A:$A=$B7)*('CPI Data'!$B:$B=$C7)*('CPI Data'!$C:$C=$D7),0))} -> 370.9 | I7: {=INDEX('CPI Data'!AJ:AJ,MATCH(1,('CPI Data'!$A:$A=$B7)*('CPI Data'!$B:$B=$C7)*('CPI Data'!$C:$C=$D7),0))} -> 347.6 | J7: {=INDEX('CPI Data'!AK:AK,MATCH(1,('CPI Data'!$A:$A=$B7)*('CPI Data'!$B:$B=$C7)*('CPI Data'!$C:$C=$D7),0))} -> 547.9
C8: CPI Total | E8: =SUM(E5:E7) -> 6932.7 | F8: =SUM(F5:F7) -> 1651.8 | G8: =SUM(G5:G7) -> 1584.1 | H8: =SUM(H5:H7) -> 1111.4 | I8: =SUM(I5:I7) -> 1043.6 | J8: =SUM(J5:J7) -> 1646.1
C9: Inflation Rate% | E9: =E8/SUM($E$8:$J$8) -> 0.49626692 | F9: =F8/SUM($E$8:$J$8) -> 0.11824162 | G9: =G8/SUM($E$8:$J$8) -> 0.11339542 | H9: =H8/SUM($E$8:$J$8) -> 0.0795579 | I9: =I8/SUM($E$8:$J$8) -> 0.074704539 | J9: =J8/SUM($E$8:$J$8) -> 0.1178336
B11: Rural+Urban | C11: 2023 | D11: May
B12: Broader Categories and Their Contributions(May 2023)
B13: CPI Category | C13: CPI Value | D13: Contribution Rate %
B14: Food | C14: {=INDEX('CPI Data'!AF:AF,MATCH(1,('CPI Data'!$A:$A=$B$11)*('CPI Data'!$B:$B=$C$11)*('CPI Data'!$C:$C=$D$11),0))} -> 2306.9 | D14: =(C14/SUM($C$14:$C$19)) -> 0.49563854
B15: Clothing | C15: {=INDEX('CPI Data'!AG:AG,MATCH(1,('CPI Data'!$A:$A=B11)*('CPI Data'!$B:$B=C11)*('CPI Data'!$C:$C=D11),0))} -> 553.2 | D15: =(C15/SUM($C$14:$C$19)) -> 0.11885528
B16: Essential | C16: {=INDEX('CPI Data'!AH:AH,MATCH(1,('CPI Data'!$A:$A=B11)*('CPI Data'!$B:$B=C11)*('CPI Data'!$C:$C=D11),0))} -> 527.9 | D16: =(C16/SUM($C$14:$C$19)) -> 0.11341956
B17: Health | C17: {=INDEX('CPI Data'!AI:AI,MATCH(1,('CPI Data'!$A:$A=B11)*('CPI Data'!$B:$B=C11)*('CPI Data'!$C:$C=D11),0))} -> 370.9 | D17: =(C17/SUM($C$14:$C$19)) -> 0.079688037
B18: Energy | C18: {=INDEX('CPI Data'!AJ:AJ,MATCH(1,('CPI Data'!$A:$A=B11)*('CPI Data'!$B:$B=C11)*('CPI Data'!$C:$C=D11),0))} -> 347.6 | D18: =(C18/SUM($C$14:$C$19)) -> 0.074682021
B19: Luxury | C19: {=INDEX('CPI Data'!AK:AK,MATCH(1,('CPI Data'!$A:$A=B11)*('CPI Data'!$B:$B=C11)*('CPI Data'!$C:$C=D11),0))} -> 547.9 | D19: =(C19/SUM($C$14:$C$19)) -> 0.11771657
B20: Total | C20: =SUM(C14:C19) -> 4654.4 | D20: =SUM(D14:D19) -> 1
B23: Broader Categories and Their Contributions (May 2023)
B24: CPI Category | C24: Rural Contribution (%) | D24: Urban Contribution (%) | E24: Rural + Urban Contribution (%)
B25: Food | C25: 0.4900522 | D25: 0.50315672 | E25: 0.49563854
B26: Clothing | C26: 0.12191939 | D26: 0.11392187 | E26: 0.11885528
B27: Essential | C27: 0.11460294 | D27: 0.11215497 | E27: 0.11341956
B28: Health | C28: 0.079732158 | D28: 0.079251869 | E28: 0.079688037
B29: Energy | C29: 0.075346569 | D29: 0.074080459 | E29: 0.074682021
B30: Luxury | C30: 0.11834674 | D30: 0.11743412 | E30: 0.11771657
B31: Total | C31: 1 | D31: 1 | E31: 1
B34: Interpretation & Analysis
B35: Food is the dominant contributor (≈50%), making it the single largest driver of overall inflation.
B36: Clothing (~12%) and Essentials (~11%) follow as major spending categories across households.
B37: Health (~8%) and Energy (~7%) contribute moderately, indicating stable but smaller inflationary impact.
B38: Luxury goods (~12%) show significant spending, reflecting shifting lifestyle and rising disposable incomes.
B39: Rural and Urban patterns remain similar, with food dominating both regions.
B41: Insights
B42: Food inflation has the strongest influence on total CPI — stabilizing food supply chains should be a priority.
B43: Uniform rural–urban spending trends enable consistent nationwide inflation-control strategies.
B44: Health and energy categories are less volatile, contributing to CPI stability.
B45: Luxury spending in rural areas signals improving income levels and evolving consumption behaviour.

Sheet 2. Inflation & Deflation Rate
A1: 2. YOY INCREASE IN CPI (Rural + Urban) INFLATION FROM 2017 to 2023 FOR THE ENTIRE BASKET
B4: Calcuated YOY increment growth by Urban+Rural
B5: Sector | C5: Year | D5: January | E5: December | F5: Y-O-Y %
B6: Rural+Urban | C6: 2017 | D6: =AVERAGEIFS('CPI Data'!$AE:$AE,'CPI Data'!$B:$B,'2. Inflation & Deflation Rate'!$C6,'CPI Data'!$C:$C,'2. Inflation & Deflation Rate'!$D$5,'CPI Data'!$A:$A,'2. Inflation & Deflation Rate'!$B$6) -> 130.3 | E6: =AVERAGEIFS('CPI Data'!$AE:$AE,'CPI Data'!$B:$B,'2. Inflation & Deflation Rate'!$C6,'CPI Data'!$C:$C,'2. Inflation & Deflation Rate'!$E$5,'CPI Data'!$A:$A,'2. Inflation & Deflation Rate'!$B$6) -> 137.2 | F6: =(E6-D6)/D6 -> 0.05295472
C7: 2018 | D7: =AVERAGEIFS('CPI Data'!$AE:$AE,'CPI Data'!$B:$B,'2. Inflation & Deflation Rate'!$C7,'CPI Data'!$C:$C,'2. Inflation & Deflation Rate'!$D$5,'CPI Data'!$A:$A,'2. Inflation & Deflation Rate'!$B$6) -> 136.9 | E7: =AVERAGEIFS('CPI Data'!$AE:$AE,'CPI Data'!$B:$B,'2. Inflation & Deflation Rate'!$C7,'CPI Data'!$C:$C,'2. Inflation & Deflation Rate'!$E$5,'CPI Data'!$A:$A,'2. Inflation & Deflation Rate'!$B$6) -> 140.1 | F7: =(E7-D7)/D7 -> 0.023374726
C8: 2019 | D8: =AVERAGEIFS('CPI Data'!$AE:$AE,'CPI Data'!$B:$B,'2. Inflation & Deflation Rate'!$C8,'CPI Data'!$C:$C,'2. Inflation & Deflation Rate'!$D$5,'CPI Data'!$A:$A,'2. Inflation & Deflation Rate'!$B$6) -> 139.6 | E8: =AVERAGEIFS('CPI Data'!$AE:$AE,'CPI Data'!$B:$B,'2. Inflation & Deflation Rate'!$C8,'CPI Data'!$C:$C,'2. Inflation & Deflation Rate'!$E$5,'CPI Data'!$A:$A,'2. Inflation & Deflation Rate'!$B$6) -> 150.4 | F8: =(E8-D8)/D8 -> 0.077363897
C9: 2020 | D9: =AVERAGEIFS('CPI Data'!$AE:$AE,'CPI Data'!$B:$B,'2. Inflation & Deflation Rate'!$C9,'CPI Data'!$C:$C,'2. Inflation & Deflation Rate'!$D$5,'CPI Data'!$A:$A,'2. Inflation & Deflation Rate'!$B$6) -> 150.2 | E9: =AVERAGEIFS('CPI Data'!$AE:$AE,'CPI Data'!$B:$B,'2. Inflation & Deflation Rate'!$C9,'CPI Data'!$C:$C,'2. Inflation & Deflation Rate'!$E$5,'CPI Data'!$A:$A,'2. Inflation & Deflation Rate'!$B$6) -> 158.9 | F9: =(E9-D9)/D9 -> 0.05792277
C10: 2021 | D10: =AVERAGEIFS('CPI Data'!$AE:$AE,'CPI Data'!$B:$B,'2. Inflation & Deflation Rate'!$C10,'CPI Data'!$C:$C,'2. Inflation & Deflation Rate'!$D$5,'CPI Data'!$A:$A,'2. Inflation & Deflation Rate'!$B$6) -> 157.3 | E10: =AVERAGEIFS('CPI Data'!$AE:$AE,'CPI Data'!$B:$B,'2. Inflation & Deflation Rate'!$C10,'CPI Data'!$C:$C,'2. Inflation & Deflation Rate'!$E$5,'CPI Data'!$A:$A,'2. Inflation & Deflation Rate'!$B$6) -> 166.2 | F10: =(E10-D10)/D10 -> 0.056579784
C11: 2022 | D11: =AVERAGEIFS('CPI Data'!$AE:$AE,'CPI Data'!$B:$B,'2. Inflation & Deflation Rate'!$C11,'CPI Data'!$C:$C,'2. Inflation & Deflation Rate'!$D$5,'CPI Data'!$A:$A,'2. Inflation & Deflation Rate'!$B$6) -> 165.7 | E11: =AVERAGEIFS('CPI Data'!$AE:$AE,'CPI Data'!$B:$B,'2. Inflation & Deflation Rate'!$C11,'CPI Data'!$C:$C,'2. Inflation & Deflation Rate'!$E$5,'CPI Data'!$A:$A,'2. Inflation & Deflation Rate'!$B$6) -> 175.7 | F11: =(E11-D11)/D11 -> 0.06035003
B16: Broader categories wise Y-O-Y inflation
B17: Year | C17: Month | D17: Food | E17: Clothing | F17: Essential | G17: Health | H17: Energy | I17: Lux
B18: 2019 | C18: January | D18: =AVERAGEIFS('CPI Data'!AF:AF,'CPI Data'!$A:$A,'2. Inflation & Deflation Rate'!$B$6,'CPI Data'!$B:$B,'2. Inflation & Deflation Rate'!$B18,'CPI Data'!$C:$C,'2. Inflation & Deflation Rate'!$C18) -> 1753.4 | E18: =AVERAGEIFS('CPI Data'!AG:AG,'CPI Data'!$A:$A,'2. Inflation & Deflation Rate'!$B$6,'CPI Data'!$B:$B,'2. Inflation & Deflation Rate'!$B18,'CPI Data'!$C:$C,'2. Inflation & Deflation Rate'!$C18) -> 433 | F18: =AVERAGEIFS('CPI Data'!AH:AH,'CPI Data'!$A:$A,'2. Inflation & Deflation Rate'!$B$6,'CPI Data'!$B:$B,'2. Inflation & Deflation Rate'!$B18,'CPI Data'!$C:$C,'2. Inflation & Deflation Rate'!$C18) -> 441.5 | G18: =AVERAGEIFS('CPI Data'!AI:AI,'CPI Data'!$A:$A,'2. Inflation & Deflation Rate'!$B$6,'CPI Data'!$B:$B,'2. Inflation & Deflation Rate'!$B18,'CPI Data'!$C:$C,'2. Inflation & Deflation Rate'!$C18) -> 277.9 | H18: =AVERAGEIFS('CPI Data'!AJ:AJ,'CPI Data'!$A:$A,'2. Inflation & Deflation Rate'!$B$6,'CPI Data'!$B:$B,'2. Inflation & Deflation Rate'!$B18,'CPI Data'!$C:$C,'2. Inflation & Deflation Rate'!$C18) -> 262.8 | I18: =AVERAGEIFS('CPI Data'!AK:AK,'CPI Data'!$A:$A,'2. Inflation & Deflation Rate'!$B$6,'CPI Data'!$B:$B,'2. Inflation & Deflation Rate'!$B18,'CPI Data'!$C:$C,'2. Inflation & Deflation Rate'!$C18) -> 436.8
B19: 2019 | C19: December | D19: =AVERAGEIFS('CPI Data'!AF:AF,'CPI Data'!$A:$A,'2. Inflation & Deflation Rate'!$B$6,'CPI Data'!$B:$B,'2. Inflation & Deflation Rate'!$B19,'CPI Data'!$C:$C,'2. Inflation & Deflation Rate'!$C19) -> 1946.1 | E19: =AVERAGEIFS('CPI Data'!AG:AG,'CPI Data'!$A:$A,'2. Inflation & Deflation Rate'!$B$6,'CPI Data'!$B:$B,'2. Inflation & Deflation Rate'!$B19,'CPI Data'!$C:$C,'2. Inflation & Deflation Rate'!$C19) -> 440.6 | F19: =AVERAGEIFS('CPI Data'!AH:AH,'CPI Data'!$A:$A,'2. Inflation & Deflation Rate'!$B$6,'CPI Data'!$B:$B,'2. Inflation & Deflation Rate'!$B19,'CPI Data'!$C:$C,'2. Inflation & Deflation Rate'!$C19) -> 454.3 | G19: =AVERAGEIFS('CPI Data'!AI:AI,'CPI Data'!$A:$A,'2. Inflation & Deflation Rate'!$B$6,'CPI Data'!$B:$B,'2. Inflation & Deflation Rate'!$B19,'CPI Data'!$C:$C,'2. Inflation & Deflation Rate'!$C19) -> 290.8 | H19: =AVERAGEIFS('CPI Data'!AJ:AJ,'CPI Data'!$A:$A,'2. Inflation & Deflation Rate'!$B$6,'CPI Data'!$B:$B,'2. Inflation & Deflation Rate'!$B19,'CPI Data'!$C:$C,'2. Inflation & Deflation Rate'!$C19) -> 273.5 | I19: =AVERAGEIFS('CPI Data'!AK:AK,'CPI Data'!$A:$A,'2. Inflation & Deflation Rate'!$B$6,'CPI Data'!$B:$B,'2. Inflation & Deflation Rate'!$B19,'CPI Data'!$C:$C,'2. Inflation & Deflation Rate'!$C19) -> 453.3
C20: Inflation Rate | D20: =(D19-D18)/D18 -> 0.10990076 | E20: =(E19-E18)/E18 -> 0.017551963 | F20: =(F19-F18)/F18 -> 0.028992072 | G20: =(G19-G18)/G18 -> 0.046419575 | H20: =(H19-H18)/H18 -> 0.040715373 | I20: =(I19-I18)/I18 -> 0.037774725
B36: Interpretation and Analysis:
B38: As graph is depicting hieghest inflation in year 2019 with 7.7% increment.
B39: Reason: Due to 11% increment in Food & Beverages category

Sheet 3.MoM & AbsChange
A1: 3. A M-O-M PRICE TRENDS OF BROADER FOOD BUCKET FOR JUN 2022- MAY 23
A4: Food Inflation/Deflation Rate (MoM)%
A5: Time Period | B5: Food & Beverages | C5: Food Inflation Rate (MoM)%
A6: 2022 May | B6: =AVERAGEIF('CPI Data'!$D:$D,'3.MoM & AbsChange'!$A6,'CPI Data'!$Q:$Q) -> 173.86667
A7: 2022 June | B7: =AVERAGEIF('CPI Data'!$D:$D,'3.MoM & AbsChange'!$A7,'CPI Data'!$Q:$Q) -> 175.53333 | C7: =((B7-B6)/B6) -> 0.0095858896
A8: 2022 July | B8: =AVERAGEIF('CPI Data'!$D:$D,'3.MoM & AbsChange'!$A8,'CPI Data'!$Q:$Q) -> 175.63333 | C8: =((B8-B7)/B7) -> 0.00056969237
A9: 2022 August | B9: =AVERAGEIF('CPI Data'!$D:$D,'3.MoM & AbsChange'!$A9,'CPI Data'!$Q:$Q) -> 176.86667 | C9: =((B9-B8)/B8) -> 0.0070222054
A10: 2022 September | B10: =AVERAGEIF('CPI Data'!$D:$D,'3.MoM & AbsChange'!$A10,'CPI Data'!$Q:$Q) -> 178.36667 | C10: =((B10-B9)/B9) -> 0.0084809649
